Workbook

Sheet Inputs
A1: Aircraft configuration inputs: eVTOL vs seaplane
A2: Blue = value copied from the JSON config (or from the scenario file where the section says so). 'n/a' = the field does not exist for that propulsion architecture. Sources: examples/wildfire/data/aircraft/example_aircraft_1.json, example_seaplane_1.json and examples/wildfire/data/scenarios/inputs/Palisades5sp5ev_multiweight.json (read 2026-09-20).
A4: Field | B4: Unit | C4: eVTOL (example_aircraft_1) | D4: Seaplane (example_seaplane_1) | E4: What the simulation does with it
A5: Identity and type
A6: icon | B6: - | C6: evtol.svg | D6: seaplane.svg | E6: GUI sprite only; no effect on behaviour.
A7: takeoff_landing_type | B7: - | C7: vertipad | D7: water | E7: Base compatibility: an airport accepts an aircraft only if this type is in the airport's takeoff_landing_types. The scenario airports declare none, so they default to all three (runway, vertipad, water) and both aircraft can use either base. 'vertipad' + electric + retransition_duration > 0 also switches on the eVTOL-only energy guards (Behaviour sheet).
A8: architecture | B8: - | C8: electric | D8: conventional | E8: Selects the propulsion model: BatteryElectricPropulsion (energy in kJ, aircraft mass constant) vs ConventionalPropulsion (fuel in kg, mass drops as fuel burns).
A9: autonomous | B9: - | C9: FALSE | D9: FALSE | E9: Stored on the agent; not read by any tactic or model code.
A10: Mass and payload
A11: mtom | B11: kg | C11: 1988.448 | D11: 6495.57 | E11: Validated at load: empty_mass + payload + fuel mass must not exceed it. Also caps the start mass used in propellant estimates.
A12: empty_mass | B12: kg | C12: 1628.448 | D12: 3788 | E12: Current mass = empty_mass + water on board + fuel mass. For the eVTOL the battery is inside empty_mass (propellant mass = 0).
A13: payload | B13: kg | C13: 360 | D13: 1300 | E13: Water carried per sortie. The whole payload is released in one drop; sets the drop patch area (Derived sheet).
A14: flow_rate | B14: m3/s | C14: 1.2 | D14: 1.2 | E14: Suppressant flow rate; sets the drop patch width (Legendre et al. 2014 fit).
A15: Scooping
A16: can_scoop | B16: - | C16: TRUE | D16: TRUE | E16: If True and a feasible water body exists, the aircraft refills at water instead of at base whenever the estimated round-trip propellant is lower.
A17: scooping_distance | B17: m | C17: 6 | D17: 200 | E17: Length of the rectangle that must fit entirely inside a water polygon for that body to be a feasible scoop site (AgentInput comment: fixed wing ~1341 m typical; rotorcraft = largest length x 2).
A18: span | B18: m | C18: 6 | D18: 18 | E18: Width of that rectangle (fixed wing: span x 2; rotorcraft: rotor diameter).
A19: Propulsion (propulsion_input)
A20: propellant_unit | B20: - | C20: kJ | D20: kg | E20: Unit of the propellant figures below.
A21: total_propellant | B21: kJ / kg | C21: 492445.3 | D21: 1407.57 | E21: Battery energy (eVTOL) or fuel mass (seaplane) when full.
A22: reserve_propellant | B22: kJ / kg | C22: 33253.6 | D22: 420.57 | E22: Never planned into a mission. Usable = total - reserve. The sim raises 'ran out of propellant' only when usable + reserve < 0.
A23: battery_swap_enabled | B23: - | C23: TRUE | D23: n/a | E23: eVTOL: at base the battery is swapped (energy jumps to full once battery_swap_time has elapsed) instead of being charged.
A24: battery_swap_time | B24: s | C24: 600 | D24: n/a | E24: Time on the ground at base before the eVTOL is full again.
A25: charging_power | B25: kW | C25: 359.019 | D25: n/a | E25: Only used if battery swap is disabled; unused with the current config.
A26: refueling_rate | B26: kg/s | C26: n/a | D26: 15.14 | E26: Seaplane fuel refill rate at base.
A27: fuel_specific_energy | B27: kJ/kg | C27: n/a | D27: 44000 | E27: Default (not in the JSON); only converts fuel to energy for output logging.
A28: safety_factor | B28: - | C28: 1 | D28: 1 | E28: Default (not in the JSON); multiplies propellant-required estimates.
A29: Flight profile (profile_parameters)
A30: taxi_out_duration | B30: s | C30: 60 | D30: 120 | E30: Not flown by the wildfire tactic (there is no taxi task and trajectories are generated without taxi).
A31: taxi_in_duration | B31: s | C31: 60 | D31: 120 | E31: Not flown by the wildfire tactic.
A32: transition_duration | B32: s | C32: 45.887 | D32: 0 | E32: Hold after every takeoff, billed at transition power/fc, before cruise-climb. 0 s = skipped (seaplane).
A33: retransition_duration | B33: s | C33: 45.887 | D33: 0 | E33: Hold before every landing at base and before the water descent. 0 s = skipped (seaplane).
A34: takeoff_altitude | B34: m | C34: 15.24 | D34: 457.2 | E34: Height above field elevation that the takeoff phase climbs to.
A35: takeoff_climb_rate | B35: m/s | C35: 0.508 | D35: 3.81 | E35: Vertical speed during the takeoff phase.
A36: takeoff_ground_speed | B36: m/s | C36: 0 | D36: 23 | E36: 0 = vertical takeoff (no horizontal motion during the takeoff task).
A37: cruise_climb_rate | B37: m/s | C37: 3.556 | D37: 6.96 | E37: Vertical speed of the cruise-climb phase.
A38: cruise_climb_ground_speed | B38: m/s | C38: 51.272 | D38: 100 | E38: Ground speed of the cruise-climb phase.
A39: cruise_altitude | B39: m | C39: 457.2 | D39: 3000 | E39: Target cruise altitude (absolute). Raised automatically if terrain + takeoff/landing altitude is higher.
A40: cruise_speed | B40: m/s | C40: 90 | D40: 100 | E40: Ground speed of the level cruise phase.
A41: cruise_descent_rate | B41: m/s | C41: 3.556 | D41: 6.96 | E41: Vertical speed of the cruise-descent phase.
...

Sheet Derived
A1: Derived performance figures (all formulas reference the Inputs sheet)
A2: Black = formula. Formulas mirror the code: AircraftProfileParameters (sosid/model/abm/trajectory.py), generate_straight_trajectory, SuppressionUAV.suppression_patch (agents.py) and the propulsion refill logic (propulsion.py).
A4: Quantity | B4: Unit | C4: eVTOL (example_aircraft_1) | D4: Seaplane (example_seaplane_1) | E4: Note
A5: Propellant
A6: Usable propellant (total - reserve) | B6: kJ / kg | C6: =Inputs!$C$21-Inputs!$C$22 | D6: =Inputs!$D$21-Inputs!$D$22 | E6: What the mission planner may spend.
A7: Usable energy | B7: kWh | C7: =C6/3600 | D7: =D6*Inputs!$D$27/3600 | E7: Seaplane figure is chemical energy in the fuel (44 MJ/kg), not shaft energy, so it is not directly comparable to battery kWh.
A8: Reserve share of total | B8: % | C8: =Inputs!$C$22/Inputs!$C$21 | D8: =Inputs!$D$22/Inputs!$D$21 | E8: Fraction that is never planned into a sortie.
A9: Full refill time at base | B9: s | C9: =IF(Inputs!$C$23,Inputs!$C$24,C6/Inputs!$C$25) | D9: =D6/Inputs!$D$26 | E9: eVTOL: battery swap is a flat wait. Seaplane: usable fuel / refueling_rate, worst case from an empty usable tank. The refuel task ends when propellant equals total usable.
A10: Full refill time at base | B10: min | C10: =C9/60 | D10: =D9/60
A11: Takeoff (from base, and the hop after a water scoop)
A12: Takeoff mode | B12: - | C12: =IF(Inputs!$C$36=0,"vertical","ground roll + climb") | D12: =IF(Inputs!$D$36=0,"vertical","ground roll + climb") | E12: takeoff task: altitude rises at takeoff_climb_rate each step; the aircraft only moves forward if takeoff_ground_speed > 0.
A13: Takeoff duration | B13: s | C13: =Inputs!$C$34/Inputs!$C$35 | D13: =Inputs!$D$34/Inputs!$D$35 | E13: takeoff_altitude / takeoff_climb_rate (AircraftProfileParameters.takeoff_duration).
A14: Takeoff ground distance | B14: m | C14: =C13*Inputs!$C$36 | D14: =D13*Inputs!$D$36 | E14: Duration x takeoff_ground_speed.
A15: Transition hold after takeoff | B15: s | C15: =Inputs!$C$32 | D15: =Inputs!$D$32 | E15: Stationary hold billed at transition power/fc. A 0 s hold completes on the same step.
A16: Apron to start of cruise-climb | B16: s | C16: =C13+C15 | D16: =D13+D15 | E16: Takeoff + transition.
A17: Last of the fleet departs after | B17: min | C17: =(Inputs!$C$49-1)*Inputs!$C$51/60 | D17: =(Inputs!$D$49-1)*Inputs!$D$51/60 | E17: One departure per takeoff_interval per base, after response_time.
A18: Cruise climb, cruise and descent
A19: Cruise-climb duration to cruise altitude | B19: s | C19: =(Inputs!$C$39-Inputs!$C$34)/Inputs!$C$37 | D19: =(Inputs!$D$39-Inputs!$D$34)/Inputs!$D$37 | E19: (cruise_altitude - takeoff_altitude) / cruise_climb_rate, assuming the base is at sea level.
A20: Cruise-climb horizontal distance | B20: km | C20: =C19*Inputs!$C$38/1000 | D20: =D19*Inputs!$D$38/1000 | E20: Duration x cruise_climb_ground_speed.
A21: Cruise-descent horizontal distance to a firefront | B21: km | C21: =(Inputs!$C$39-Inputs!$C$55)/Inputs!$C$41*Inputs!$C$42/1000 | D21: =(Inputs!$D$39-Inputs!$D$55)/Inputs!$D$41*Inputs!$D$42/1000 | E21: Descent from cruise altitude to suppression_altitude AGL (terrain assumed flat).
A22: Shortest base-to-fire leg that reaches cruise altitude | B22: km | C22: =C20+C21 | D22: =D20+D21 | E22: Shorter legs fly a triangular climb/descent and never enter the CRUISE state (generate_straight_trajectory). On a Palisades-sized map the seaplane therefore spends almost every leg in CRUISE_CLIMB / CRUISE_DESCENT.
A23: Cruise speed | B23: km/h | C23: =Inputs!$C$40*3.6 | D23: =Inputs!$D$40*3.6
A24: Cruise-climb ground speed | B24: km/h | C24: =Inputs!$C$38*3.6 | D24: =Inputs!$D$38*3.6
A25: Time to cover 10 km at cruise speed | B25: min | C25: =10000/Inputs!$C$40/60 | D25: =10000/Inputs!$D$40/60 | E25: Illustrative only.
A26: Landing at base
A27: Retransition hold before landing | B27: s | C27: =Inputs!$C$33 | D27: =Inputs!$D$33 | E27: Stationary hold billed at retransition power/fc.
A28: Landing duration | B28: s | C28: =Inputs!$C$43/Inputs!$C$44 | D28: =Inputs!$D$43/Inputs!$D$44 | E28: landing_altitude / landing_descent_rate.
A29: Landing ground distance | B29: m | C29: =C28*Inputs!$C$45 | D29: =D28*Inputs!$D$45 | E29: Duration x landing_ground_speed.
A30: Retransition + landing | B30: s | C30: =C27+C28 | D30: =D27+D28
A31: Water resupply
A32: Descent target over water | B32: m AGL | C32: =Inputs!$C$54 | D32: =Inputs!$D$54 | E32: Trajectory to a WATER destination ends here; the landing task then completes immediately because the target is already reached.
A33: Retransition hold before the water descent | B33: s | C33: =Inputs!$C$33 | D33: =Inputs!$D$33 | E33: Both hold for retransition_duration, but only the eVTOL switches to the RETRANSITION state (and pays retransition power) during it.
A34: Scoop hold (LOITER) | B34: s | C34: =Inputs!$C$53 | D34: =Inputs!$D$53 | E34: Billed at loiter power/fc; payload becomes full at the end.
A35: Climb after scoop to takeoff target | B35: m | C35: =MAX(0,Inputs!$C$43-Inputs!$C$54) | D35: =MAX(0,Inputs!$D$43-Inputs!$D$54) | E35: After the scoop the takeoff task targets field elevation + landing_altitude (initiate_takeoff with no trajectory).
A36: Post-scoop climb duration | B36: s | C36: =C35/Inputs!$C$35 | D36: =D35/Inputs!$D$35 | E36: Billed at takeoff power/fc.
A37: Ground distance during post-scoop climb | B37: m | C37: =C36*Inputs!$C$36 | D37: =D36*Inputs!$D$36
A38: Scoop rectangle area | B38: m2 | C38: =Inputs!$C$17*Inputs!$C$18 | D38: =Inputs!$D$17*Inputs!$D$18 | E38: scooping_distance x span must fit inside the water polygon (evaluate_water_source_feasibility).
A39: Feasible OSM water bodies on Palisades | B39: count | C39: 41 | D39: 1 | E39: From the generate_water_sets run of 2026-06-03 (set 2 = eVTOL footprint, set 1 = seaplane footprint); Pyrenees: 116 vs 19. Re-run generate_water_sets.py to confirm.
A40: Drop patch (SuppressionUAV.suppression_patch, Legendre et al. 2014)
A41: Drop ground area | B41: m2 | C41: =1.028*Inputs!$C$13 | D41: =1.028*Inputs!$D$13 | E41: 1.028 m2 per kg of payload.
...

Sheet Propulsion
A1: Energy and fuel consumption per flight state
A2: eVTOL: power [kW = kJ/s] is linearly interpolated between the two table masses (make_interp_spline, k=1). Seaplane: fuel flow [kg/s] is a linear function of mass through the two table points (the propulsion ODE integrates it exactly). Both extrapolate outside the table.
A4: eVTOL (example_aircraft_1)
A5: Table mass 1 | B5: 1628 | C5: kg
A6: Table mass 2 | B6: 2128 | C6: kg
A7: Empty mass (no water) | B7: =Inputs!$C$12 | C7: kg
A8: Loaded mass (with water) | B8: =Inputs!$C$12+Inputs!$C$13 | C8: kg
A9: Usable energy | B9: =Derived!$C$6 | C9: kJ
A11: Flight state | B11: Power @ 1628 kg [kW] | C11: Power @ 2128 kg [kW] | D11: Power @ empty [kW] | E11: Power @ loaded [kW] | F11: Endurance @ empty [min] | G11: Endurance @ loaded [min] | K11: When it is billed
A12: taxi_out | B12: 32.654 | C12: 42.612 | D12: =B12+(C12-B12)*($B$7-$B$5)/($B$6-$B$5) | E12: =B12+(C12-B12)*($B$8-$B$5)/($B$6-$B$5) | F12: =IF(D12=0,"-",$B$9/D12/60) | G12: =IF(E12=0,"-",$B$9/E12/60) | K12: Never (no taxi task).
A13: takeoff | B13: 332.452 | C13: 433.089 | D13: =B13+(C13-B13)*($B$7-$B$5)/($B$6-$B$5) | E13: =B13+(C13-B13)*($B$8-$B$5)/($B$6-$B$5) | F13: =IF(D13=0,"-",$B$9/D13/60) | G13: =IF(E13=0,"-",$B$9/E13/60) | K13: 30 s vertical climb from base (loaded) and the 0.24 m hop after a scoop.
A14: transition | B14: 274.267 | C14: 330.716 | D14: =B14+(C14-B14)*($B$7-$B$5)/($B$6-$B$5) | E14: =B14+(C14-B14)*($B$8-$B$5)/($B$6-$B$5) | F14: =IF(D14=0,"-",$B$9/D14/60) | G14: =IF(E14=0,"-",$B$9/E14/60) | K14: 45.9 s stationary hold after every takeoff.
A15: cruise_climb | B15: 350.8 | C15: 385.032 | D15: =B15+(C15-B15)*($B$7-$B$5)/($B$6-$B$5) | E15: =B15+(C15-B15)*($B$8-$B$5)/($B$6-$B$5) | F15: =IF(D15=0,"-",$B$9/D15/60) | G15: =IF(E15=0,"-",$B$9/E15/60) | K15: Climb legs.
A16: cruise | B16: 268.507 | C16: 285.914 | D16: =B16+(C16-B16)*($B$7-$B$5)/($B$6-$B$5) | E16: =B16+(C16-B16)*($B$8-$B$5)/($B$6-$B$5) | F16: =IF(D16=0,"-",$B$9/D16/60) | G16: =IF(E16=0,"-",$B$9/E16/60) | K16: Level legs once cruise altitude is reached (needs a leg of about 12 km).
A17: cruise_descent | B17: 195.196 | C17: 195.027 | D17: =B17+(C17-B17)*($B$7-$B$5)/($B$6-$B$5) | E17: =B17+(C17-B17)*($B$8-$B$5)/($B$6-$B$5) | F17: =IF(D17=0,"-",$B$9/D17/60) | G17: =IF(E17=0,"-",$B$9/E17/60) | K17: Descent legs to fire, water or base.
A18: retransition | B18: 274.267 | C18: 330.716 | D18: =B18+(C18-B18)*($B$7-$B$5)/($B$6-$B$5) | E18: =B18+(C18-B18)*($B$8-$B$5)/($B$6-$B$5) | F18: =IF(D18=0,"-",$B$9/D18/60) | G18: =IF(E18=0,"-",$B$9/E18/60) | K18: 45.9 s hold before every base landing and before every water descent.
A19: landing | B19: 332.452 | C19: 433.089 | D19: =B19+(C19-B19)*($B$7-$B$5)/($B$6-$B$5) | E19: =B19+(C19-B19)*($B$8-$B$5)/($B$6-$B$5) | F19: =IF(D19=0,"-",$B$9/D19/60) | G19: =IF(E19=0,"-",$B$9/E19/60) | K19: 30 s vertical descent at base (empty).
A20: taxi_in | B20: 32.654 | C20: 42.612 | D20: =B20+(C20-B20)*($B$7-$B$5)/($B$6-$B$5) | E20: =B20+(C20-B20)*($B$8-$B$5)/($B$6-$B$5) | F20: =IF(D20=0,"-",$B$9/D20/60) | G20: =IF(E20=0,"-",$B$9/E20/60) | K20: Never (no taxi task).
A21: loiter | B21: 277.489 | C21: 294.145 | D21: =B21+(C21-B21)*($B$7-$B$5)/($B$6-$B$5) | E21: =B21+(C21-B21)*($B$8-$B$5)/($B$6-$B$5) | F21: =IF(D21=0,"-",$B$9/D21/60) | G21: =IF(E21=0,"-",$B$9/E21/60) | K21: 30 s scoop hold at water.
A22: hover | B22: 326.543 | C22: 426.117 | D22: =B22+(C22-B22)*($B$7-$B$5)/($B$6-$B$5) | E22: =B22+(C22-B22)*($B$8-$B$5)/($B$6-$B$5) | F22: =IF(D22=0,"-",$B$9/D22/60) | G22: =IF(E22=0,"-",$B$9/E22/60) | K22: HOVER state is never entered by the wildfire tactic.
A24: Seaplane (example_seaplane_1)
A25: Dry mass (empty + full fuel, no water) | B25: =Inputs!$D$12+Inputs!$D$21 | C25: kg
A26: Full mass (+ water) | B26: =B25+Inputs!$D$13 | C26: kg
A27: Usable fuel | B27: =Derived!$D$6 | C27: kg
A29: Flight state | B29: Table mass 1 [kg] | C29: fc @ mass 1 [kg/s] | D29: Table mass 2 [kg] | E29: fc @ mass 2 [kg/s] | F29: fc @ dry mass [kg/s] | G29: fc @ full mass [kg/s] | H29: Endurance @ dry [h] | I29: Endurance @ full [h] | K29: When it is billed / caveat
A30: taxi_out | C30: 0.015734265 | F30: =IF(D30="",C30,C30+(E30-C30)*($B$25-B30)/(D30-B30)) | G30: =IF(D30="",C30,C30+(E30-C30)*($B$26-B30)/(D30-B30)) | H30: =IF(F30=0,"-",$B$27/F30/3600) | I30: =IF(G30=0,"-",$B$27/G30/3600) | K30: Never (no taxi task).
A31: takeoff | C31: 0.09107378 | F31: =IF(D31="",C31,C31+(E31-C31)*($B$25-B31)/(D31-B31)) | G31: =IF(D31="",C31,C31+(E31-C31)*($B$26-B31)/(D31-B31)) | H31: =IF(F31=0,"-",$B$27/F31/3600) | I31: =IF(G31=0,"-",$B$27/G31/3600) | K31: 120 s ground-roll climb to 457 m from base, and the ~116 s climb from 15 m after a scoop.
A32: transition | C32: 0 | F32: =IF(D32="",C32,C32+(E32-C32)*($B$25-B32)/(D32-B32)) | G32: =IF(D32="",C32,C32+(E32-C32)*($B$26-B32)/(D32-B32)) | H32: =IF(F32=0,"-",$B$27/F32/3600) | I32: =IF(G32=0,"-",$B$27/G32/3600) | K32: 0 s hold: never billed.
A33: cruise_climb | B33: 3875 | C33: 0.0515411 | D33: 3897 | E33: 0.0590774 | F33: =IF(D33="",C33,C33+(E33-C33)*($B$25-B33)/(D33-B33)) | G33: =IF(D33="",C33,C33+(E33-C33)*($B$26-B33)/(D33-B33)) | H33: =IF(F33=0,"-",$B$27/F33/3600) | I33: =IF(G33=0,"-",$B$27/G33/3600) | K33: CAVEAT: table keys are 22 kg apart and 1300-2600 kg below operating mass, so the linear extrapolation gives 10-18x the tabulated flow. Most Palisades legs are flown in this state. Worth checking against the source data.
A34: cruise | B34: 3690 | C34: 0.0345278 | D34: 3874 | E34: 0.0348847 | F34: =IF(D34="",C34,C34+(E34-C34)*($B$25-B34)/(D34-B34)) | G34: =IF(D34="",C34,C34+(E34-C34)*($B$26-B34)/(D34-B34)) | H34: =IF(F34=0,"-",$B$27/F34/3600) | I34: =IF(G34=0,"-",$B$27/G34/3600) | K34: Level legs; only reached on legs longer than about 79 km.
A35: cruise_descent | B35: 3690 | C35: 0.0345278 | D35: 3874 | E35: 0.0348847 | F35: =IF(D35="",C35,C35+(E35-C35)*($B$25-B35)/(D35-B35)) | G35: =IF(D35="",C35,C35+(E35-C35)*($B$26-B35)/(D35-B35)) | H35: =IF(F35=0,"-",$B$27/F35/3600) | I35: =IF(G35=0,"-",$B$27/G35/3600) | K35: Descent legs (same table as cruise).
A36: retransition | C36: 0 | F36: =IF(D36="",C36,C36+(E36-C36)*($B$25-B36)/(D36-B36)) | G36: =IF(D36="",C36,C36+(E36-C36)*($B$26-B36)/(D36-B36)) | H36: =IF(F36=0,"-",$B$27/F36/3600) | I36: =IF(G36=0,"-",$B$27/G36/3600) | K36: 0 s hold: never billed.
A37: landing | C37: 0.02176823 | F37: =IF(D37="",C37,C37+(E37-C37)*($B$25-B37)/(D37-B37)) | G37: =IF(D37="",C37,C37+(E37-C37)*($B$26-B37)/(D37-B37)) | H37: =IF(F37=0,"-",$B$27/F37/3600) | I37: =IF(G37=0,"-",$B$27/G37/3600) | K37: 120 s descent at base from 457 m.
A38: taxi_in | C38: 0.015734265 | F38: =IF(D38="",C38,C38+(E38-C38)*($B$25-B38)/(D38-B38)) | G38: =IF(D38="",C38,C38+(E38-C38)*($B$26-B38)/(D38-B38)) | H38: =IF(F38=0,"-",$B$27/F38/3600) | I38: =IF(G38=0,"-",$B$27/G38/3600) | K38: Never (no taxi task).
A39: loiter | C39: 0.0345278 | F39: =IF(D39="",C39,C39+(E39-C39)*($B$25-B39)/(D39-B39)) | G39: =IF(D39="",C39,C39+(E39-C39)*($B$26-B39)/(D39-B39)) | H39: =IF(F39=0,"-",$B$27/F39/3600) | I39: =IF(G39=0,"-",$B$27/G39/3600) | K39: 30 s scoop hold at water.
A40: hover | C40: 0 | F40: =IF(D40="",C40,C40+(E40-C40)*($B$25-B40)/(D40-B40)) | G40: =IF(D40="",C40,C40+(E40-C40)*($B$26-B40)/(D40-B40)) | H40: =IF(F40=0,"-",$B$27/F40/3600) | I40: =IF(G40=0,"-",$B$27/G40/3600) | K40: Default 0; HOVER state is never entered.
A42: Fixed (non-cruise) segments of one base -> fire -> water -> ... -> base cycle
A43: Segment | B43: eVTOL duration [s] | C43: eVTOL power [kW] | D43: eVTOL energy [kJ] | E43: Seaplane duration [s] | F43: Seaplane fc [kg/s] | G43: Seaplane fuel [kg] | K43: Mass assumed
A44: Takeoff from base | B44: =Derived!$C$13 | C44: =E13 | D44: =B44*C44 | E44: =Derived!$D$13 | F44: =G31 | G44: =E44*F44 | K44: Loaded (water on board).
A45: Transition after takeoff | B45: =Derived!$C$15 | C45: =E14 | D45: =B45*C45 | E45: =Derived!$D$15 | F45: =G32 | G45: =E45*F45 | K45: Loaded.
...

Sheet Behaviour
A1: How each aircraft behaves in the simulation
A2: Based on examples/wildfire/firefighter_model (suppression_tactics.py, agents.py, model.py, tactic_pieces/) and src/sosid/model/abm (trajectory.py, propulsion.py, special_agents.py) at commit 4d7a69c plus the working tree of 2026-09-20.
A4: Topic | B4: eVTOL (example_aircraft_1) | C4: Seaplane (example_seaplane_1) | D4: Where in the code
A5: Base compatibility | B5: Type 'vertipad'. Scenario airports declare no takeoff_landing_types, so they accept every type. The five eVTOLs start at base 1, whose coordinates come straight from the JSON (33.94, -118.42, next to LAX). | C5: Type 'water'. Same default: any base accepts it. The five seaplanes start at base 0, which the loader replaces with the OSM airport nearest the first ignition centre (deploy_osm_airport_locations + k_nearest_airports = 1), so the JSON's placeholder coordinates for base 0 are never used. | D5: special_agents.py BaseAirTrafficManager.is_compatible_with; simulation.py AirportInput
A6: Departure from base | B6: Holds response_time, queues for clearance (one departure per takeoff_interval per base), then climbs vertically 15.24 m at 0.508 m/s (30 s, no ground motion) at takeoff power, then holds 45.9 s TRANSITION at transition power, then starts the cruise-climb toward the chosen firefront. Since commit 305db82 the takeoff target is field elevation + takeoff_altitude; before that it climbed to the stale inbound trajectory's start altitude and could burn ~70% of the battery. | C6: Same queue. Takeoff is a ground-roll climb: 23 m/s ground speed, 3.81 m/s climb, 457.2 m in 120 s covering 2.76 km, at takeoff_fc. transition_duration is 0 so the transition hold completes on the same step. | D6: suppression_tactics.py await_takeoff_clearance, trigger_takeoff_from_base, initiate_takeoff, takeoff, transition_segment
A7: Climb and cruise | B7: Cruise-climb at 3.556 m/s and 51.3 m/s ground speed to 457.2 m, then cruise at 90 m/s. Reaching cruise altitude needs a leg of about 12 km; shorter legs are a triangular climb/descent. | C7: Cruise-climb at 6.96 m/s and 100 m/s to 3000 m, cruise at 100 m/s. Reaching cruise altitude needs a leg of about 79 km, so on Palisades it almost never cruises level and spends most of each leg in CRUISE_CLIMB (where its fuel flow is extrapolated, see Propulsion sheet). | D7: trajectory.py generate_straight_trajectory
A8: Attack | B8: Descends to 50 m AGL over the firefront and releases the whole 360 kg as an elliptical patch of about 21 m x 23 m (4 x 5 cells at 5 m). | C8: Descends to 50 m AGL and releases 1300 kg as a patch of about 75 m x 23 m (15 x 5 cells at 5 m): 3.6x the area per drop. | D8: agents.py suppression_patch; tactic_pieces/suppress.py DirectSuppress
A9: Choosing where to refill | B9: After the drop it compares the propellant for a round trip to the nearest feasible water body against a round trip to the nearest base and picks the cheaper. With a 6 m x 6 m scoop rectangle nearly every OSM water body is feasible (41 on Palisades with water set 2), so it usually scoops. Then check_energy verifies attack leg + a loaded bail-out leg to base; otherwise it returns to base. | C9: Same comparison, but its 200 m x 18 m rectangle fits inside very few bodies (1 on Palisades, 19 on Pyrenees), so it often has to fly back to base for water. Same check_energy test. | D9: suppression_tactics.py select_suppressant_source, check_energy; model.py evaluate_water_source_feasibility
A10: Scooping at water | B10: Before the descent it holds 45.9 s in RETRANSITION (billed at retransition power), descends along the cruise-descent slope to 15 m AGL, the landing task completes immediately, then it loiters 30 s at loiter power and is refilled. It then 'takes off' 0.24 m to 15.24 m and holds another 45.9 s transition before climbing away. The energy estimate for a water trip includes the retransition hold. | C10: No retransition (0 s). Descends to 15 m AGL, loiters 30 s at loiter_fc, refills, then flies a takeoff climb from 15 m to 457 m at takeoff_fc (about 116 s, 2.7 km ground track) before the cruise-climb. This post-scoop climb is not booked by the water-trip estimate. | D10: suppression_tactics.py retransition_before_resupply, land_to_resupply, resupply_payload, finish_resupply; agents.py estimate_propellant_for_journey
A11: Return and turnaround at base | B11: Flies to the nearest base, holds 45.9 s RETRANSITION, descends vertically 15.24 m in 30 s at landing power, then sits in ENERGIZE until the battery swap completes: a flat 600 s. Payload is refilled instantly. Then it re-queues for takeoff. | C11: Flies to base, no retransition, lands over 120 s / 2.76 km at landing_fc, then refuels at 15.14 kg/s: about 65 s from an empty usable tank. Payload refilled instantly, re-queues for takeoff. | D11: suppression_tactics.py return_to_base, land_to_base, resupply, refuel; propulsion.py _refill_propellant
A12: Energy guards | B12: Electric + vertipad + retransition > 0 turns on four eVTOL-only guards: (1) every step outside takeoff/landing/return tasks it checks it can still reach the nearest base and diverts if not; (2) before chasing a firefront it checks propellant for the chase plus a return (EvtolFollowFirefrontTrackPOI, re-applied when the PPO policy swaps track_poi); (3) water-trip estimates add the retransition hold; (4) when the base is chosen as the cheaper 'water stop' it does a full swap rather than a payload-only stop. | C12: None of the four. Only the post-drop check_energy test applies. This is deliberate: applying the base-resupply rule fleet-wide changed seaplane results on Pyrenees, and the seaplane carries enough fuel margin not to need it. | D12: agents.py _divert_evtol_to_base_if_return_energy_is_low, has_propellant_for_firefront_and_return; suppression_tactics.py track_poi setter, initiate_resupply
A13: Propellant model | B13: Battery energy in kJ; aircraft mass never changes with charge. Power per state is interpolated linearly between the 1628 kg and 2128 kg table points; operating mass (1628-1988 kg) lies inside the table. Usable 459,192 kJ (127.6 kWh) gives roughly 19-28 min of flight depending on state. | C13: Fuel in kg burned through an exact exponential-in-time solution; mass falls as fuel burns. Fuel-flow tables are keyed at 3690-3897 kg while the aircraft operates at 5196-6496 kg, so every mass-dependent state is extrapolated: cruise by 8-16%, cruise-climb by 10-18x. Usable fuel 987 kg gives about 7 h in cruise but only 17-32 min in cruise-climb at the extrapolated rate. | D13: propulsion.py BatteryElectricPropulsion, ConventionalPropulsion, _create_exact_consumption_function
A14: Depletion behaviour | B14: If usable + reserve ever drops below zero the sim raises ValueError('Agent ran out of electric propellant') and prints an EVTOL_PROPELLANT_DEPLETION diagnostic with the sortie history. | C14: Same ValueError for fuel, without the diagnostic dump. | D14: propulsion.py _validate_propellant; agents.py _log_propellant_depletion
A15: Unused config fields | B15: icon (GUI only), autonomous, taxi_out/taxi_in durations, loiter_speed, charging_power (swap enabled), hover_power (state never entered). | C15: icon, autonomous, taxi durations, loiter_speed, transition/retransition fuel flows (0 s holds), hover_fc.
